[START] task_id:829d9311578aab72fe793fffcb6ba723 mission:caller pid:48605
[DRIVER] task_id:829d9311578aab72fe793fffcb6ba723 mission:caller pid:48605
[ERROR] task_id:829d9311578aab72fe793fffcb6ba723 pid:48605
SUCCESS
[START!] task_id:7f27f18c5e274fdea6f2c6ac064f67ae mission:TEST pid:49036
[DRIVER] task_id:7f27f18c5e274fdea6f2c6ac064f67ae mission:TEST pid:49036
[ERROR!] task_id:7f27f18c5e274fdea6f2c6ac064f67ae pid:49036
SUCCESS
[START!] task_id:2f0b545e6371431806dc172e5dba92e8 mission:TEST pid:49045
[DRIVER] task_id:2f0b545e6371431806dc172e5dba92e8 mission:TEST pid:49045
[ERROR!] task_id:2f0b545e6371431806dc172e5dba92e8 pid:49045
SUCCESS
[START!] task_id:77ac17496ecb17064f61c807ee9b14f8 mission:TEST pid:49103
[DRIVER] task_id:77ac17496ecb17064f61c807ee9b14f8 mission:TEST pid:49103
[ERROR!] task_id:77ac17496ecb17064f61c807ee9b14f8 pid:49103
SUCCESS
[START!] task_id:79002f9db616359e40ca9d19ef5e2a5b mission:TEST pid:49163
[DRIVER] task_id:79002f9db616359e40ca9d19ef5e2a5b mission:TEST pid:49163
[SUCCESS] task_id:79002f9db616359e40ca9d19ef5e2a5b mission:TEST pid:49163
[START!] task_id:ba7e5bb66d44aac21847161aa368bd49 mission:TEST pid:49274
[DRIVER] task_id:ba7e5bb66d44aac21847161aa368bd49 mission:TEST pid:49274
[SUCCESS] task_id:ba7e5bb66d44aac21847161aa368bd49 mission:TEST pid:49274
[START!] task_id:344573625682796ec17d8c0ad1f00d11 mission:TEST pid:49280
[DRIVER] task_id:344573625682796ec17d8c0ad1f00d11 mission:TEST pid:49280
[SUCCESS] task_id:344573625682796ec17d8c0ad1f00d11 mission:TEST pid:49280
[START!] task_id:ebb9f6f18dcb1b0d775184eda6958486 mission:TEST pid:49285
[DRIVER] task_id:ebb9f6f18dcb1b0d775184eda6958486 mission:TEST pid:49285
[SUCCESS] task_id:ebb9f6f18dcb1b0d775184eda6958486 mission:TEST pid:49285
[START!] task_id:dfeaac2a6a6869cbc5f9ad5b11a4ea80 mission:TEST pid:49291
[DRIVER] task_id:dfeaac2a6a6869cbc5f9ad5b11a4ea80 mission:TEST pid:49291
[SUCCESS] task_id:dfeaac2a6a6869cbc5f9ad5b11a4ea80 mission:TEST pid:49291
[START!] task_id:376f36de545cdba04fc06452ffeadc6d mission:TEST pid:49294
[DRIVER] task_id:376f36de545cdba04fc06452ffeadc6d mission:TEST pid:49294
[SUCCESS] task_id:376f36de545cdba04fc06452ffeadc6d mission:TEST pid:49294
[START!] task_id:799766083762d9234623d584b63eacc8 mission:TEST pid:49299
[DRIVER] task_id:799766083762d9234623d584b63eacc8 mission:TEST pid:49299
[SUCCESS] task_id:799766083762d9234623d584b63eacc8 mission:TEST pid:49299
[ERROR] task_id:452a0201880b5cdf9fdb8871205e2bec pid:69192
        Msg: Traceback (most recent call last):
  File "/Users/shawn/NCCU/4v/SE/islam/islamapp/scraper/scraper_controller.py", line 165, in run
    self.mission = map_task_type_to_mission(self.task.type)
  File "/Users/shawn/NCCU/4v/SE/islam/islamapp/scraper/mission/mission.py", line 31, in map_task_type_to_mission
    raise Exception("Invalid task type")
Exception: Invalid task type

[ERROR] task_id:54a454d7523cd2a3fec36363cdc7057a pid:69869
        Msg: Traceback (most recent call last):
  File "/Users/shawn/NCCU/4v/SE/islam/islamapp/scraper/scraper_controller.py", line 165, in run
    self.mission = map_task_type_to_mission(self.task.type)
  File "/Users/shawn/NCCU/4v/SE/islam/islamapp/scraper/mission/mission.py", line 31, in map_task_type_to_mission
    raise Exception("Invalid task type")
Exception: Invalid task type

[START] task_id: 79b812e1fc5f22c1f19b4bbbc5dfbd22 mission: FOLLOWING_AND_FOLLOWERS pid: 74062
[START] task_id: 79b812e1fc5f22c1f19b4bbbc5dfbd22 mission: FOLLOWING_AND_FOLLOWERS pid: 74064
[ERROR] task_id:79b812e1fc5f22c1f19b4bbbc5dfbd22 pid:74064
        Msg: Traceback (most recent call last):
  File "/Users/shawn/NCCU/4v/SE/islam/islamapp/.ISLAMENV/lib/python3.9/site-packages/instagrapi/mixins/private.py", line 360, in _send_private_request
    response.raise_for_status()
  File "/Users/shawn/NCCU/4v/SE/islam/islamapp/.ISLAMENV/lib/python3.9/site-packages/requests/models.py", line 1021, in raise_for_status
    raise HTTPError(http_error_msg, response=self)
requests.exceptions.HTTPError: 400 Client Error: Bad Request for url: https://i.instagram.com/api/v1/accounts/login/

During handling of the above exception, another exception occurred:

Traceback (most recent call last):
  File "/Users/shawn/NCCU/4v/SE/islam/islamapp/scraper/mission/mission.py", line 42, in scrape_followers_and_following
    instagrapi = Instagrapi(account, password, task_id)
  File "/Users/shawn/NCCU/4v/SE/islam/islamapp/scraper/instagrapi.py", line 15, in __init__
    self.cl.login(username, password)
  File "/Users/shawn/NCCU/4v/SE/islam/islamapp/.ISLAMENV/lib/python3.9/site-packages/instagrapi/mixins/auth.py", line 403, in login
    logged = self.private_request("accounts/login/", data, login=True)
  File "/Users/shawn/NCCU/4v/SE/islam/islamapp/.ISLAMENV/lib/python3.9/site-packages/instagrapi/mixins/private.py", line 535, in private_request
    raise e
  File "/Users/shawn/NCCU/4v/SE/islam/islamapp/.ISLAMENV/lib/python3.9/site-packages/instagrapi/mixins/private.py", line 520, in private_request
    self._send_private_request(endpoint, **kwargs)
  File "/Users/shawn/NCCU/4v/SE/islam/islamapp/.ISLAMENV/lib/python3.9/site-packages/instagrapi/mixins/private.py", line 403, in _send_private_request
    raise RateLimitError(**last_json)
instagrapi.exceptions.RateLimitError: Please wait a few minutes before you try again.

During handling of the above exception, another exception occurred:

Traceback (most recent call last):
  File "/Users/shawn/NCCU/4v/SE/islam/islamapp/scraper/scraper_controller.py", line 177, in run
    result = self.mission({}, self.task)
  File "/Users/shawn/NCCU/4v/SE/islam/islamapp/scraper/util.py", line 23, in caller
    raise exception
  File "/Users/shawn/NCCU/4v/SE/islam/islamapp/scraper/util.py", line 20, in caller
    return func(*args, **kwargs)
  File "/Users/shawn/NCCU/4v/SE/islam/islamapp/scraper/mission/mission.py", line 48, in scrape_followers_and_following
    raise Exception(exception)
Exception: Please wait a few minutes before you try again.

[ERROR] task_id:79b812e1fc5f22c1f19b4bbbc5dfbd22 pid:74062
        Msg: Traceback (most recent call last):
  File "/Users/shawn/NCCU/4v/SE/islam/islamapp/scraper/mission/mission.py", line 43, in scrape_followers_and_following
    raw_data = instagrapi.get_users_relative_followers_following(target_ig_id)
  File "/Users/shawn/NCCU/4v/SE/islam/islamapp/scraper/instagrapi.py", line 80, in get_users_relative_followers_following
    followers_list = self.get_user_followers(scraped_ig_id)
  File "/Users/shawn/NCCU/4v/SE/islam/islamapp/scraper/instagrapi.py", line 26, in get_user_followers
    followers = self.cl.user_followers(user_id, amout=10)
TypeError: user_followers() got an unexpected keyword argument 'amout'

During handling of the above exception, another exception occurred:

Traceback (most recent call last):
  File "/Users/shawn/NCCU/4v/SE/islam/islamapp/scraper/scraper_controller.py", line 177, in run
    result = self.mission({}, self.task)
  File "/Users/shawn/NCCU/4v/SE/islam/islamapp/scraper/util.py", line 23, in caller
    raise exception
  File "/Users/shawn/NCCU/4v/SE/islam/islamapp/scraper/util.py", line 20, in caller
    return func(*args, **kwargs)
  File "/Users/shawn/NCCU/4v/SE/islam/islamapp/scraper/mission/mission.py", line 48, in scrape_followers_and_following
    raise Exception(exception)
Exception: user_followers() got an unexpected keyword argument 'amout'

[START] task_id: 7c3ac1669d05f920eafe75aaaad26b6b mission: FOLLOWING_AND_FOLLOWERS pid: 74205
[START] task_id: 7c3ac1669d05f920eafe75aaaad26b6b mission: FOLLOWING_AND_FOLLOWERS pid: 74207
[ERROR] task_id:7c3ac1669d05f920eafe75aaaad26b6b pid:74207
        Msg: Traceback (most recent call last):
  File "/Users/shawn/NCCU/4v/SE/islam/islamapp/.ISLAMENV/lib/python3.9/site-packages/instagrapi/mixins/private.py", line 360, in _send_private_request
    response.raise_for_status()
  File "/Users/shawn/NCCU/4v/SE/islam/islamapp/.ISLAMENV/lib/python3.9/site-packages/requests/models.py", line 1021, in raise_for_status
    raise HTTPError(http_error_msg, response=self)
requests.exceptions.HTTPError: 400 Client Error: Bad Request for url: https://i.instagram.com/api/v1/accounts/login/

During handling of the above exception, another exception occurred:

Traceback (most recent call last):
  File "/Users/shawn/NCCU/4v/SE/islam/islamapp/scraper/mission/mission.py", line 41, in scrape_followers_and_following
    instagrapi = Instagrapi(account, password, task_id)
  File "/Users/shawn/NCCU/4v/SE/islam/islamapp/scraper/instagrapi.py", line 15, in __init__
    self.cl.login(username, password)
  File "/Users/shawn/NCCU/4v/SE/islam/islamapp/.ISLAMENV/lib/python3.9/site-packages/instagrapi/mixins/auth.py", line 403, in login
    logged = self.private_request("accounts/login/", data, login=True)
  File "/Users/shawn/NCCU/4v/SE/islam/islamapp/.ISLAMENV/lib/python3.9/site-packages/instagrapi/mixins/private.py", line 535, in private_request
    raise e
  File "/Users/shawn/NCCU/4v/SE/islam/islamapp/.ISLAMENV/lib/python3.9/site-packages/instagrapi/mixins/private.py", line 520, in private_request
    self._send_private_request(endpoint, **kwargs)
  File "/Users/shawn/NCCU/4v/SE/islam/islamapp/.ISLAMENV/lib/python3.9/site-packages/instagrapi/mixins/private.py", line 403, in _send_private_request
    raise RateLimitError(**last_json)
instagrapi.exceptions.RateLimitError: Please wait a few minutes before you try again.

During handling of the above exception, another exception occurred:

Traceback (most recent call last):
  File "/Users/shawn/NCCU/4v/SE/islam/islamapp/scraper/scraper_controller.py", line 177, in run
    result = self.mission({}, self.task)
  File "/Users/shawn/NCCU/4v/SE/islam/islamapp/scraper/mission/mission.py", line 47, in scrape_followers_and_following
    raise Exception(exception)
Exception: Please wait a few minutes before you try again.

[ERROR] task_id:7c3ac1669d05f920eafe75aaaad26b6b pid:74205
        Msg: Traceback (most recent call last):
  File "/Users/shawn/NCCU/4v/SE/islam/islamapp/scraper/mission/mission.py", line 42, in scrape_followers_and_following
    raw_data = instagrapi.get_users_relative_followers_following(target_ig_id)
  File "/Users/shawn/NCCU/4v/SE/islam/islamapp/scraper/instagrapi.py", line 80, in get_users_relative_followers_following
    followers_list = self.get_user_followers(scraped_ig_id)
  File "/Users/shawn/NCCU/4v/SE/islam/islamapp/scraper/instagrapi.py", line 26, in get_user_followers
    followers = self.cl.user_followers(user_id, amout=10)
TypeError: user_followers() got an unexpected keyword argument 'amout'

During handling of the above exception, another exception occurred:

Traceback (most recent call last):
  File "/Users/shawn/NCCU/4v/SE/islam/islamapp/scraper/scraper_controller.py", line 177, in run
    result = self.mission({}, self.task)
  File "/Users/shawn/NCCU/4v/SE/islam/islamapp/scraper/mission/mission.py", line 47, in scrape_followers_and_following
    raise Exception(exception)
Exception: user_followers() got an unexpected keyword argument 'amout'

[START] task_id: f6ded96d74cefafc3a1c55c9134fa19f mission: FOLLOWING_AND_FOLLOWERS pid: 75395
[START] task_id: f6ded96d74cefafc3a1c55c9134fa19f mission: FOLLOWING_AND_FOLLOWERS pid: 75397
[ERROR] task_id:f6ded96d74cefafc3a1c55c9134fa19f pid:75397
        Msg: Traceback (most recent call last):
  File "/Users/shawn/NCCU/4v/SE/islam/islamapp/.ISLAMENV/lib/python3.9/site-packages/instagrapi/mixins/private.py", line 360, in _send_private_request
    response.raise_for_status()
  File "/Users/shawn/NCCU/4v/SE/islam/islamapp/.ISLAMENV/lib/python3.9/site-packages/requests/models.py", line 1021, in raise_for_status
    raise HTTPError(http_error_msg, response=self)
requests.exceptions.HTTPError: 400 Client Error: Bad Request for url: https://i.instagram.com/api/v1/accounts/login/

During handling of the above exception, another exception occurred:

Traceback (most recent call last):
  File "/Users/shawn/NCCU/4v/SE/islam/islamapp/scraper/mission/mission.py", line 41, in scrape_followers_and_following
    instagrapi = Instagrapi(account, password, task_id)
  File "/Users/shawn/NCCU/4v/SE/islam/islamapp/scraper/instagrapi.py", line 15, in __init__
    self.cl.login(username, password)
  File "/Users/shawn/NCCU/4v/SE/islam/islamapp/.ISLAMENV/lib/python3.9/site-packages/instagrapi/mixins/auth.py", line 403, in login
    logged = self.private_request("accounts/login/", data, login=True)
  File "/Users/shawn/NCCU/4v/SE/islam/islamapp/.ISLAMENV/lib/python3.9/site-packages/instagrapi/mixins/private.py", line 535, in private_request
    raise e
  File "/Users/shawn/NCCU/4v/SE/islam/islamapp/.ISLAMENV/lib/python3.9/site-packages/instagrapi/mixins/private.py", line 520, in private_request
    self._send_private_request(endpoint, **kwargs)
  File "/Users/shawn/NCCU/4v/SE/islam/islamapp/.ISLAMENV/lib/python3.9/site-packages/instagrapi/mixins/private.py", line 403, in _send_private_request
    raise RateLimitError(**last_json)
instagrapi.exceptions.RateLimitError: Please wait a few minutes before you try again.

During handling of the above exception, another exception occurred:

Traceback (most recent call last):
  File "/Users/shawn/NCCU/4v/SE/islam/islamapp/scraper/scraper_controller.py", line 177, in run
    result = self.mission({}, self.task)
  File "/Users/shawn/NCCU/4v/SE/islam/islamapp/scraper/mission/mission.py", line 47, in scrape_followers_and_following
    raise Exception(exception)
Exception: Please wait a few minutes before you try again.

[FINSH] task_id:f6ded96d74cefafc3a1c55c9134fa19f mission:FOLLOWING_AND_FOLLOWERS pid:75395
[START] task_id: 027a9848223ea333450f2209af223706 mission: FOLLOWING_AND_FOLLOWERS pid: 75515
[FINSH] task_id:027a9848223ea333450f2209af223706 mission:FOLLOWING_AND_FOLLOWERS pid:75515
[START] task_id: e04a81ee4ce32ff515fb257b39c47622 mission: FOLLOWING_AND_FOLLOWERS pid: 75639
[FINSH] task_id:e04a81ee4ce32ff515fb257b39c47622 mission:FOLLOWING_AND_FOLLOWERS pid:75639
[START] task_id: 8672d253a0e3bee22af6dcd024f39752 mission: FOLLOWING_AND_FOLLOWERS pid: 75746
[FINSH] task_id:8672d253a0e3bee22af6dcd024f39752 mission:FOLLOWING_AND_FOLLOWERS pid:75746
[START] task_id: 8672d253a0e3bee22af6dcd024f39752 mission: FOLLOWING_AND_FOLLOWERS pid: 75789
[FINSH] task_id:8672d253a0e3bee22af6dcd024f39752 mission:FOLLOWING_AND_FOLLOWERS pid:75789
[START] task_id: 2c568ae0267b5157f63ee9e519a8df1d mission: FOLLOWING_AND_FOLLOWERS pid: 75928
[FINSH] task_id:2c568ae0267b5157f63ee9e519a8df1d mission:FOLLOWING_AND_FOLLOWERS pid:75928
[START] task_id: f338a1d96bbba4930d1d6098e5070b86 mission: FOLLOWING_AND_FOLLOWERS pid: 76608
[FINSH] task_id:f338a1d96bbba4930d1d6098e5070b86 mission:FOLLOWING_AND_FOLLOWERS pid:76608
[START] task_id: f338a1d96bbba4930d1d6098e5070b86 mission: FOLLOWING_AND_FOLLOWERS pid: 76630
[FINSH] task_id:f338a1d96bbba4930d1d6098e5070b86 mission:FOLLOWING_AND_FOLLOWERS pid:76630
[START] task_id: f90824518109cae155e3003faf5a3fe8 mission: FOLLOWING_AND_FOLLOWERS pid: 76758
[FINSH] task_id:f90824518109cae155e3003faf5a3fe8 mission:FOLLOWING_AND_FOLLOWERS pid:76758
[START] task_id: f90824518109cae155e3003faf5a3fe8 mission: FOLLOWING_AND_FOLLOWERS pid: 76764
[FINSH] task_id:f90824518109cae155e3003faf5a3fe8 mission:FOLLOWING_AND_FOLLOWERS pid:76764
[START] task_id: bdac5e7715b6b6eaa4738e2f6308870a mission: FOLLOWER_AND_FOLLOWING pid: 78389
[ERROR] task_id:bdac5e7715b6b6eaa4738e2f6308870a pid:78389
        Msg: Traceback (most recent call last):
  File "/Users/shawn/NCCU/4v/SE/islam/islamapp/.ISLAMENV/lib/python3.9/site-packages/instagrapi/mixins/private.py", line 360, in _send_private_request
    response.raise_for_status()
  File "/Users/shawn/NCCU/4v/SE/islam/islamapp/.ISLAMENV/lib/python3.9/site-packages/requests/models.py", line 1021, in raise_for_status
    raise HTTPError(http_error_msg, response=self)
requests.exceptions.HTTPError: 400 Client Error: Bad Request for url: https://i.instagram.com/api/v1/accounts/login/

During handling of the above exception, another exception occurred:

Traceback (most recent call last):
  File "/Users/shawn/NCCU/4v/SE/islam/islamapp/scraper/mission/mission.py", line 41, in scrape_followers_and_following
    instagrapi = Instagrapi(account, password, task_id)
  File "/Users/shawn/NCCU/4v/SE/islam/islamapp/scraper/instagrapi.py", line 15, in __init__
    self.cl.login(username, password)
  File "/Users/shawn/NCCU/4v/SE/islam/islamapp/.ISLAMENV/lib/python3.9/site-packages/instagrapi/mixins/auth.py", line 403, in login
    logged = self.private_request("accounts/login/", data, login=True)
  File "/Users/shawn/NCCU/4v/SE/islam/islamapp/.ISLAMENV/lib/python3.9/site-packages/instagrapi/mixins/private.py", line 535, in private_request
    raise e
  File "/Users/shawn/NCCU/4v/SE/islam/islamapp/.ISLAMENV/lib/python3.9/site-packages/instagrapi/mixins/private.py", line 520, in private_request
    self._send_private_request(endpoint, **kwargs)
  File "/Users/shawn/NCCU/4v/SE/islam/islamapp/.ISLAMENV/lib/python3.9/site-packages/instagrapi/mixins/private.py", line 405, in _send_private_request
    raise BadPassword(**last_json)
instagrapi.exceptions.BadPassword: The password you entered is incorrect. Please try again.

During handling of the above exception, another exception occurred:

Traceback (most recent call last):
  File "/Users/shawn/NCCU/4v/SE/islam/islamapp/scraper/scraper_controller.py", line 177, in run
    result = self.mission({}, self.task)
  File "/Users/shawn/NCCU/4v/SE/islam/islamapp/scraper/mission/mission.py", line 47, in scrape_followers_and_following
    raise Exception(exception)
Exception: The password you entered is incorrect. Please try again.

[START] task_id: bdac5e7715b6b6eaa4738e2f6308870a mission: FOLLOWER_AND_FOLLOWING pid: 78394
[ERROR] task_id:bdac5e7715b6b6eaa4738e2f6308870a pid:78394
        Msg: Traceback (most recent call last):
  File "/Users/shawn/NCCU/4v/SE/islam/islamapp/.ISLAMENV/lib/python3.9/site-packages/instagrapi/mixins/private.py", line 360, in _send_private_request
    response.raise_for_status()
  File "/Users/shawn/NCCU/4v/SE/islam/islamapp/.ISLAMENV/lib/python3.9/site-packages/requests/models.py", line 1021, in raise_for_status
    raise HTTPError(http_error_msg, response=self)
requests.exceptions.HTTPError: 400 Client Error: Bad Request for url: https://i.instagram.com/api/v1/accounts/login/

During handling of the above exception, another exception occurred:

Traceback (most recent call last):
  File "/Users/shawn/NCCU/4v/SE/islam/islamapp/scraper/mission/mission.py", line 41, in scrape_followers_and_following
    instagrapi = Instagrapi(account, password, task_id)
  File "/Users/shawn/NCCU/4v/SE/islam/islamapp/scraper/instagrapi.py", line 15, in __init__
    self.cl.login(username, password)
  File "/Users/shawn/NCCU/4v/SE/islam/islamapp/.ISLAMENV/lib/python3.9/site-packages/instagrapi/mixins/auth.py", line 403, in login
    logged = self.private_request("accounts/login/", data, login=True)
  File "/Users/shawn/NCCU/4v/SE/islam/islamapp/.ISLAMENV/lib/python3.9/site-packages/instagrapi/mixins/private.py", line 535, in private_request
    raise e
  File "/Users/shawn/NCCU/4v/SE/islam/islamapp/.ISLAMENV/lib/python3.9/site-packages/instagrapi/mixins/private.py", line 520, in private_request
    self._send_private_request(endpoint, **kwargs)
  File "/Users/shawn/NCCU/4v/SE/islam/islamapp/.ISLAMENV/lib/python3.9/site-packages/instagrapi/mixins/private.py", line 405, in _send_private_request
    raise BadPassword(**last_json)
instagrapi.exceptions.BadPassword: The password you entered is incorrect. Please try again.

During handling of the above exception, another exception occurred:

Traceback (most recent call last):
  File "/Users/shawn/NCCU/4v/SE/islam/islamapp/scraper/scraper_controller.py", line 177, in run
    result = self.mission({}, self.task)
  File "/Users/shawn/NCCU/4v/SE/islam/islamapp/scraper/mission/mission.py", line 47, in scrape_followers_and_following
    raise Exception(exception)
Exception: The password you entered is incorrect. Please try again.

[START] task_id: 800bafc7fe866abd8ffd3ed619e4cfcb mission: FOLLOWER_AND_FOLLOWING pid: 78439
[ERROR] task_id:800bafc7fe866abd8ffd3ed619e4cfcb pid:78439
        Msg: Traceback (most recent call last):
  File "/Users/shawn/NCCU/4v/SE/islam/islamapp/scraper/scraper_controller.py", line 181, in run
    self.data_model.create(result)
AttributeError: 'NoneType' object has no attribute 'create'

[START] task_id: 800bafc7fe866abd8ffd3ed619e4cfcb mission: FOLLOWER_AND_FOLLOWING pid: 78491
[ERROR] task_id:800bafc7fe866abd8ffd3ed619e4cfcb pid:78491
        Msg: Traceback (most recent call last):
  File "/Users/shawn/NCCU/4v/SE/islam/islamapp/scraper/scraper_controller.py", line 181, in run
    self.data_model.create(result)
AttributeError: 'NoneType' object has no attribute 'create'

